Workbook

Sheet Graph
A2: MEDIA DE CALIDADES POR GRUPOS
F6: Todos | G6: 1 año | H6: 1 a 3 años | I6: 3 a 7 años | J6: Maximo | K6: Mínimo
B7: 1 año | E7: Q_01 | F7: =Resp!L32 -> 3.525 | G7: ='1Year'!L32 -> 3.875 | H7: ='1Year3'!L32 -> 3.085 | I7: ='3Year7'!L32 -> 3.5025 | J7: =IF(F7=MAX($F$7:$F$32), F7, NA()) -> #N/A | K7: =IF(F7=MIN($F$7:$F$32), F7, NA()) -> #N/A
B8: De 1 a 3 años | E8: Q_02 | F8: =Resp!L33 -> 4.05 | G8: ='1Year'!L33 -> 3.8125 | H8: ='1Year3'!L33 -> 4 | I8: ='3Year7'!L33 -> 4.4175 | J8: =IF(F8=MAX($F$7:$F$32), F8, NA()) -> #N/A | K8: =IF(F8=MIN($F$7:$F$32), F8, NA()) -> #N/A
B9: De 3 a 7 años | E9: Q_03 | F9: =Resp!L34 -> 4.175 | G9: ='1Year'!L34 -> 4.125 | H9: ='1Year3'!L34 -> 3.75 | I9: ='3Year7'!L34 -> 4.67 | J9: =IF(F9=MAX($F$7:$F$32), F9, NA()) -> #N/A | K9: =IF(F9=MIN($F$7:$F$32), F9, NA()) -> #N/A
E10: Q_04 | F10: =Resp!L35 -> 4.225 | G10: ='1Year'!L35 -> 4.125 | H10: ='1Year3'!L35 -> 3.9175 | I10: ='3Year7'!L35 -> 4.67 | J10: =IF(F10=MAX($F$7:$F$32), F10, NA()) -> #N/A | K10: =IF(F10=MIN($F$7:$F$32), F10, NA()) -> #N/A
E11: Q_05 | F11: =Resp!L36 -> 3.25 | G11: ='1Year'!L36 -> 3.0625 | H11: ='1Year3'!L36 -> 2.75 | I11: ='3Year7'!L36 -> 4.0025 | J11: =IF(F11=MAX($F$7:$F$32), F11, NA()) -> #N/A | K11: =IF(F11=MIN($F$7:$F$32), F11, NA()) -> 3.25
E12: Q_06 | F12: =Resp!L37 -> 3.925 | G12: ='1Year'!L37 -> 3.75 | H12: ='1Year3'!L37 -> 3.7525 | I12: ='3Year7'!L37 -> 4.3325 | J12: =IF(F12=MAX($F$7:$F$32), F12, NA()) -> #N/A | K12: =IF(F12=MIN($F$7:$F$32), F12, NA()) -> #N/A
E13: Q_07 | F13: =Resp!L38 -> 3.85 | G13: ='1Year'!L38 -> 3.5 | H13: ='1Year3'!L38 -> 3.9175 | I13: ='3Year7'!L38 -> 4.2525 | J13: =IF(F13=MAX($F$7:$F$32), F13, NA()) -> #N/A | K13: =IF(F13=MIN($F$7:$F$32), F13, NA()) -> #N/A
E14: Q_08 | F14: =Resp!L39 -> 3.975 | G14: ='1Year'!L39 -> 3.75 | H14: ='1Year3'!L39 -> 4 | I14: ='3Year7'!L39 -> 4.25 | J14: =IF(F14=MAX($F$7:$F$32), F14, NA()) -> #N/A | K14: =IF(F14=MIN($F$7:$F$32), F14, NA()) -> #N/A
E15: Q_09 | F15: =Resp!L40 -> 3.725 | G15: ='1Year'!L40 -> 3.75 | H15: ='1Year3'!L40 -> 3.0825 | I15: ='3Year7'!L40 -> 4.3325 | J15: =IF(F15=MAX($F$7:$F$32), F15, NA()) -> #N/A | K15: =IF(F15=MIN($F$7:$F$32), F15, NA()) -> #N/A
E16: Q_10 | F16: =Resp!L41 -> 4.275 | G16: ='1Year'!L41 -> 4.25 | H16: ='1Year3'!L41 -> 4 | I16: ='3Year7'!L41 -> 4.585 | J16: =IF(F16=MAX($F$7:$F$32), F16, NA()) -> #N/A | K16: =IF(F16=MIN($F$7:$F$32), F16, NA()) -> #N/A
E17: Q_11 | F17: =Resp!L42 -> 4.3 | G17: ='1Year'!L42 -> 4 | H17: ='1Year3'!L42 -> 4.3325 | I17: ='3Year7'!L42 -> 4.67 | J17: =IF(F17=MAX($F$7:$F$32), F17, NA()) -> 4.3 | K17: =IF(F17=MIN($F$7:$F$32), F17, NA()) -> #N/A
E18: Q_12 | F18: =Resp!L43 -> 4.2 | G18: ='1Year'!L43 -> 4.0625 | H18: ='1Year3'!L43 -> 3.9175 | I18: ='3Year7'!L43 -> 4.67 | J18: =IF(F18=MAX($F$7:$F$32), F18, NA()) -> #N/A | K18: =IF(F18=MIN($F$7:$F$32), F18, NA()) -> #N/A
E19: Q_13 | F19: =Resp!L44 -> 3.975 | G19: ='1Year'!L44 -> 3.8125 | H19: ='1Year3'!L44 -> 4 | I19: ='3Year7'!L44 -> 4.165 | J19: =IF(F19=MAX($F$7:$F$32), F19, NA()) -> #N/A | K19: =IF(F19=MIN($F$7:$F$32), F19, NA()) -> #N/A
E20: Q_14 | F20: =Resp!L45 -> 3.7 | G20: ='1Year'!L45 -> 3.625 | H20: ='1Year3'!L45 -> 2.835 | I20: ='3Year7'!L45 -> 4.67 | J20: =IF(F20=MAX($F$7:$F$32), F20, NA()) -> #N/A | K20: =IF(F20=MIN($F$7:$F$32), F20, NA()) -> #N/A
E21: Q_15 | F21: =Resp!L46 -> 3.9 | G21: ='1Year'!L46 -> 3.375 | H21: ='1Year3'!L46 -> 4.0825 | I21: ='3Year7'!L46 -> 4.415 | J21: =IF(F21=MAX($F$7:$F$32), F21, NA()) -> #N/A | K21: =IF(F21=MIN($F$7:$F$32), F21, NA()) -> #N/A
... E32: Q_26 | F32: =Resp!L57 -> 3.898 | G32: ='1Year'!L57 -> 3.8 | H32: ='1Year3'!L57 -> 3.567 | I32: ='3Year7'!L57 -> 4.3615 | J32: =IF(F32=MAX($F$7:$F$32), F32, NA()) -> #N/A | K32: =IF(F32=MIN($F$7:$F$32), F32, NA()) -> #N/A
A37: PERFIL DE DOCENTE
F40: 1 año | G40: 1 a 3 años | H40: 3 a 7 años
F41: =COUNTIF(Resp!B:B,"1 año") -> 4 | G41: =COUNTIF(Resp!B:B,"De 1 a 3 años") -> 3 | H41: =COUNTIF(Resp!B:B,"De 3 a 7 años") -> 3
A46: FRECUENCIA DE USO DE LA IA
F48: Uso | G48: Docentes
F49: 1 | G49: =COUNTIF(Resp!C:C,F49) -> 1
F50: 2 | G50: =COUNTIF(Resp!C:C,F50) -> 1
F51: 3 | G51: =COUNTIF(Resp!C:C,F51) -> 1
F52: 4 | G52: =COUNTIF(Resp!C:C,F52) -> 3
F53: 5 | G53: =COUNTIF(Resp!C:C,F53) -> 4
A57: ACTITUD
F59: Actitud | G59: Docentes
F60: 1 | G60: =COUNTIF(Resp!D:D,F60) -> 0
F61: 2 | G61: =COUNTIF(Resp!D:D,F61) -> 1
F62: 3 | G62: =COUNTIF(Resp!D:D,F62) -> 1
F63: 4 | G63: =COUNTIF(Resp!D:D,F63) -> 4
F64: 5 | G64: =COUNTIF(Resp!D:D,F64) -> 4
A71: REFLEXIÓN
F73: Si | G73: =NA() -> #N/A
F74: No | G74: =NA() -> #N/A
F75: Con supervisión | G75: 100
G96: Claridad técnica | H96: Nivel de dificultad adecuado | I96: Calidad de los distractores | J96: Validez pedagógica | K96: Media
...

Sheet Resp
G1: PRG_01 | K1: PRG_02 | O1: PRG_03 | S1: PRG_04 | W1: PRG_05 | AA1: PRG_06 | AE1: PRG_07 | AI1: PRG_08 | AM1: PRG_09 | AQ1: PRG_10 | AU1: PRG_11 | AY1: PRG_12 | BC1: PRG_13 | BG1: PRG_14 | BK1: PRG_15 | BO1: PRG_16 | BS1: PRG_17 | BW1: PRG_18 | CA1: PRG_19 | CE1: PRG_20 | CI1: PRG_21 | CM1: PRG_22 | CQ1: PRG_23 | CU1: PRG_24 | CY1: PRG_25
F2: =ROUND(AVERAGE(G3:DB3),2) -> 3.9 | G2: =ROUND(AVERAGE(G3:J3),2) -> 3.53 | K2: =ROUND(AVERAGE(K3:N3),2) -> 4.05 | O2: =ROUND(AVERAGE(O3:R3),2) -> 4.18 | S2: =ROUND(AVERAGE(S3:V3),2) -> 4.23 | W2: =ROUND(AVERAGE(W3:Z3),2) -> 3.25 | AA2: =ROUND(AVERAGE(AA3:AD3),2) -> 3.93 | AE2: =ROUND(AVERAGE(AE3:AH3),2) -> 3.85 | AI2: =ROUND(AVERAGE(AI3:AL3),2) -> 3.98 | AM2: =ROUND(AVERAGE(AM3:AP3),2) -> 3.73 | AQ2: =ROUND(AVERAGE(AQ3:AT3),2) -> 4.28 | AU2: =ROUND(AVERAGE(AU3:AX3),2) -> 4.3 | AY2: =ROUND(AVERAGE(AY3:BB3),2) -> 4.2 | BC2: =ROUND(AVERAGE(BC3:BF3),2) -> 3.98 | BG2: =ROUND(AVERAGE(BG3:BJ3),2) -> 3.7 | BK2: =ROUND(AVERAGE(BK3:BN3),2) -> 3.9 | BO2: =ROUND(AVERAGE(BO3:BR3),2) -> 3.63 | BS2: =ROUND(AVERAGE(BS3:BV3),2) -> 3.75 | BW2: =ROUND(AVERAGE(BW3:BZ3),2) -> 4.08 | CA2: =ROUND(AVERAGE(CA3:CD3),2) -> 3.6 | CE2: =ROUND(AVERAGE(CE3:CH3),2) -> 3.7 | CI2: =ROUND(AVERAGE(CI3:CL3),2) -> 3.73 | CM2: =ROUND(AVERAGE(CM3:CP3),2) -> 3.7 | CQ2: =ROUND(AVERAGE(CQ3:CT3),2) -> 4.18 | CU2: =ROUND(AVERAGE(CU3:CX3),2) -> 4.13 | CY2: =ROUND(AVERAGE(CY3:DB3),2) -> 3.93
C3: =ROUND(AVERAGE(C5:C52),2) -> 3.8 | D3: =ROUND(AVERAGE(D5:D52),2) -> 4.1 | G3: =ROUND(AVERAGE(G5:G20),2) -> 3.8 | H3: =ROUND(AVERAGE(H5:H20),2) -> 3.2 | I3: =ROUND(AVERAGE(I5:I20),2) -> 3.7 | J3: =ROUND(AVERAGE(J5:J20),2) -> 3.4 | K3: =ROUND(AVERAGE(K5:K20),2) -> 4.2 | L3: =ROUND(AVERAGE(L5:L20),2) -> 4.2 | M3: =ROUND(AVERAGE(M5:M20),2) -> 3.7 | N3: =ROUND(AVERAGE(N5:N20),2) -> 4.1 | ... DB3: =ROUND(AVERAGE(DB5:DB20),2) -> 4
A4: Marca temporal | B4: ¿Cuantos años de experiencia tienes enseñando Python? | C4: ¿Con qué frecuencia utiliza modelos de IA para apoyarte en la práctica docente? | D4: ¿Cual es tu actitud hacia el uso de la IA en educación? | E4: ¿Consideras que la IA es capaz de sustituir la creación manual de exámenes de programación a corto plazo? | F4: Espacio libre. Deja los comentarios que creas oportunos. | G4: Pregunta 1 [Claridad técnica] | H4: Pregunta 1 [Nivel de dificultad adecuado] | I4: Pregunta 1 [Calidad de los distractores] | J4: Pregunta 1 [Validez pedagógica] | K4: Pregunta 2 [Claridad técnica] | L4: Pregunta 2 [Nivel de dificultad adecuado] | M4: Pregunta 2 [Calidad de los distractores] | N4: Pregunta 2 [Validez pedagógica] | O4: Pregunta 3 [Claridad técnica] | P4: Pregunta 3 [Nivel de dificultad adecuado] | Q4: Pregunta 3 [Calidad de los distractores] | R4: Pregunta 3 [Validez pedagógica] | S4: Pregunta 4 [Claridad técnica] | T4: Pregunta 4 [Nivel de dificultad adecuado] | U4: Pregunta 4 [Calidad de los distractores] | V4: Pregunta 4 [Validez pedagógica] | W4: Pregunta 5 [Claridad técnica] | X4: Pregunta 5 [Nivel de dificultad adecuado] | Y4: Pregunta 5 [Calidad de los distractores] | Z4: Pregunta 5 [Validez pedagógica] | AA4: Pregunta 6 [Claridad técnica] | AB4: Pregunta 6 [Nivel de dificultad adecuado] | AC4: Pregunta 6 [Calidad de los distractores] | AD4: Pregunta 6 [Validez pedagógica] | AE4: Pregunta 7 [Claridad técnica] | AF4: Pregunta 7 [Nivel de dificultad adecuado] | AG4: Pregunta 7 [Calidad de los distractores] | AH4: Pregunta 7 [Validez pedagógica] | AI4: Pregunta 8 [Claridad técnica] | AJ4: Pregunta 8 [Nivel de dificultad adecuado] | AK4: Pregunta 8 [Calidad de los distractores] | AL4: Pregunta 8 [Validez pedagógica] | AM4: Pregunta 9 [Claridad técnica] | AN4: Pregunta 9 [Nivel de dificultad adecuado] | AO4: Pregunta 9 [Calidad de los distractores] | AP4: Pregunta 9 [Validez pedagógica] | AQ4: Pregunta 10 [Claridad técnica] | AR4: Pregunta 10 [Nivel de dificultad adecuado] | AS4: Pregunta 10 [Calidad de los distractores] | AT4: Pregunta 10 [Validez pedagógica] | AU4: Pregunta 11 [Claridad técnica] | AV4: Pregunta 11 [Nivel de dificultad adecuado] | AW4: Pregunta 11 [Calidad de los distractores] | AX4: Pregunta 11 [Validez pedagógica] | AY4: Pregunta 12 [Claridad técnica] | AZ4: Pregunta 12 [Nivel de dificultad adecuado] | BA4: Pregunta 12 [Calidad de los distractores] | BB4: Pregunta 12 [Validez pedagógica] | BC4: Pregunta 13 [Claridad técnica] | BD4: Pregunta 13 [Nivel de dificultad adecuado] | BE4: Pregunta 13 [Calidad de los distractores] | BF4: Pregunta 13 [Validez pedagógica] | BG4: Pregunta 14 [Claridad técnica] | BH4: Pregunta 14 [Nivel de dificultad adecuado] | BI4: Pregunta 14 [Calidad de los distractores] | BJ4: Pregunta 14 [Validez pedagógica] | BK4: Pregunta 15 [Claridad técnica] | BL4: Pregunta 15 [Nivel de dificultad adecuado] | BM4: Pregunta 15 [Calidad de los distractores] | BN4: Pregunta 15 [Validez pedagógica] | BO4: Pregunta 16 [Claridad técnica] | BP4: Pregunta 16 [Nivel de dificultad adecuado] | BQ4: Pregunta 16 [Calidad de los distractores] | BR4: Pregunta 16 [Validez pedagógica] | BS4: Pregunta 17 [Claridad técnica] | BT4: Pregunta 17 [Nivel de dificultad adecuado] | BU4: Pregunta 17 [Calidad de los distractores] | BV4: Pregunta 17 [Validez pedagógica] | BW4: Pregunta 18 [Claridad técnica] | BX4: Pregunta 18 [Nivel de dificultad adecuado] | BY4: Pregunta 18 [Calidad de los distractores] | BZ4: Pregunta 18 [Validez pedagógica] | CA4: Pregunta 19 [Claridad técnica] | CB4: Pregunta 19 [Nivel de dificultad adecuado] | CC4: Pregunta 19 [Calidad de los distractores] | CD4: Pregunta 19 [Validez pedagógica] | CE4: Pregunta 20 [Claridad técnica] | CF4: Pregunta 20 [Nivel de dificultad adecuado] | CG4: Pregunta 20 [Calidad de los distractores] | CH4: Pregunta 20 [Validez pedagógica] | CI4: Pregunta 21 [Claridad técnica] | CJ4: Pregunta 21 [Nivel de dificultad adecuado] | CK4: Pregunta 21 [Calidad de los distractores] | CL4: Pregunta 21 [Validez pedagógica] | CM4: Pregunta 22 [Claridad técnica] | CN4: Pregunta 22 [Nivel de dificultad adecuado] | CO4: Pregunta 22 [Calidad de los distractores] | CP4: Pregunta 22 [Validez pedagógica] | CQ4: Pregunta 23 [Claridad técnica] | CR4: Pregunta 23 [Nivel de dificultad adecuado] | CS4: Pregunta 23 [Calidad de los distractores] | CT4: Pregunta 23 [Validez pedagógica] | CU4: Pregunta 24 [Claridad técnica] | CV4: Pregunta 24 [Nivel de dificultad adecuado] | CW4: Pregunta 24 [Calidad de los distractores] | CX4: Pregunta 24 [Validez pedagógica] | CY4: Pregunta 25 [Claridad técnica] | CZ4: Pregunta 25 [Nivel de dificultad adecuado] | DA4: Pregunta 25 [Calidad de los distractores] | DB4: Pregunta 25 [Validez pedagógica] | DC4: ¿Cuanto tiempo crees que te llevaría hacer un examen como este de 25 pegruntas sin ayuda de la IA?
A5: 46197.104 | B5: De 3 a 7 años | C5: 5 | D5: 5 | E5: Solo con supervisión | F5: En la última pregunta dejaría claro si te refieres a cuánto llevaría con o sin IA. Entiendo que es usando lo que quieras. | G5: 5 | H5: 3 | I5: 5 | J5: 5 | K5: 5 | L5: 5 | M5: 3 | N5: 4 | O5: 5 | P5: 5 | Q5: 5 | R5: 5 | S5: 5 | T5: 5 | U5: 5 | V5: 5 | W5: 5 | X5: 4 | Y5: 5 | Z5: 5 | AA5: 5 | AB5: 5 | AC5: 5 | AD5: 5 | AE5: 2 | AF5: 5 | AG5: 5 | AH5: 3 | AI5: 5 | AJ5: 5 | AK5: 5 | AL5: 5 | AM5: 5 | AN5: 5 | AO5: 5 | AP5: 5 | AQ5: 5 | AR5: 5 | AS5: 5 | AT5: 5 | AU5: 5 | AV5: 5 | AW5: 5 | AX5: 5 | AY5: 5 | AZ5: 5 | BA5: 5 | BB5: 5 | BC5: 5 | BD5: 5 | BE5: 5 | BF5: 5 | BG5: 5 | BH5: 5 | BI5: 5 | BJ5: 5 | BK5: 5 | BL5: 5 | BM5: 5 | BN5: 5 | BO5: 5 | BP5: 4 | BQ5: 5 | BR5: 4 | BS5: 5 | BT5: 5 | BU5: 5 | BV5: 5 | BW5: 5 | BX5: 5 | BY5: 4 | BZ5: 5 | CA5: 3 | CB5: 5 | CC5: 5 | CD5: 5 | CE5: 5 | CF5: 5 | CG5: 4 | CH5: 5 | CI5: 4 | CJ5: 4 | CK5: 2 | CL5: 4 | CM5: 5 | CN5: 5 | CO5: 5 | CP5: 4 | CQ5: 5 | CR5: 5 | CS5: 5 | CT5: 5 | CU5: 5 | CV5: 5 | CW5: 5 | CX5: 5 | CY5: 5 | CZ5: 5 | DA5: 5 | DB5: 5 | DC5: 1 hora | DH5: 1 | DI5: =CHAR(67+DH5*4) -> G | DJ5: PRG_01 | DK5: =G2 -> 3.53
A6: 46197.602 | B6: De 3 a 7 años | C6: 5 | D6: 4 | E6: Solo con supervisión | G6: 2 | H6: 2 | I6: 3 | J6: 2 | K6: 5 | L6: 5 | M6: 5 | N6: 5 | O6: 5 | P6: 5 | Q6: 5 | R6: 5 | S6: 5 | T6: 5 | U6: 5 | V6: 5 | W6: 5 | X6: 3 | Y6: 2 | Z6: 3 | AA6: 4 | AB6: 3 | AC6: 4 | AD6: 5 | AE6: 5 | AF6: 5 | AG6: 5 | AH6: 5 | AI6: 5 | AJ6: 2 | AK6: 4 | AL6: 4 | AM6: 5 | AN6: 3 | AO6: 4 | AP6: 4 | AQ6: 5 | AR6: 5 | AS6: 4 | AT6: 5 | AU6: 5 | AV6: 5 | AW6: 5 | AX6: 5 | AY6: 5 | AZ6: 5 | BA6: 5 | BB6: 5 | BC6: 4 | BD6: 2 | BE6: 4 | BF6: 4 | BG6: 5 | BH6: 5 | BI6: 5 | BJ6: 5 | BK6: 5 | BL6: 5 | BM6: 5 | BN6: 5 | BO6: 5 | BP6: 3 | BQ6: 5 | BR6: 3 | BS6: 5 | BT6: 5 | BU6: 5 | BV6: 5 | BW6: 5 | BX6: 3 | BY6: 4 | BZ6: 4 | CA6: 5 | CB6: 5 | CC6: 5 | CD6: 5 | CE6: 5 | CF6: 5 | CG6: 5 | CH6: 5 | CI6: 4 | CJ6: 3 | CK6: 4 | CL6: 3 | CM6: 4 | CN6: 3 | CO6: 3 | CP6: 3 | CQ6: 5 | CR6: 5 | CS6: 5 | CT6: 5 | CU6: 5 | CV6: 5 | CW6: 5 | CX6: 5 | CY6: 5 | CZ6: 5 | DA6: 5 | DB6: 5 | DC6: 2-3 horas | DH6: 2 | DI6: =CHAR(67+DH6*4) -> K | DJ6: PRG_02 | DK6: =K2 -> 4.05
A7: 46197.619 | B7: 1 año | C7: 5 | D7: 5 | E7: Solo con supervisión | G7: 3 | H7: 3 | I7: 3 | J7: 3 | K7: 3 | L7: 3 | M7: 2 | N7: 3 | O7: 2 | P7: 3 | Q7: 3 | R7: 2 | S7: 3 | T7: 3 | U7: 2 | V7: 2 | W7: 3 | X7: 3 | Y7: 2 | Z7: 2 | AA7: 3 | AB7: 3 | AC7: 2 | AD7: 3 | AE7: 4 | AF7: 2 | AG7: 3 | AH7: 3 | AI7: 3 | AJ7: 3 | AK7: 3 | AL7: 3 | AM7: 4 | AN7: 3 | AO7: 3 | AP7: 3 | AQ7: 4 | AR7: 2 | AS7: 4 | AT7: 3 | AU7: 3 | AV7: 3 | AW7: 3 | AX7: 3 | AY7: 3 | AZ7: 3 | BA7: 3 | BB7: 3 | BC7: 3 | BD7: 3 | BE7: 3 | BF7: 3 | BG7: 4 | BH7: 3 | BI7: 2 | BJ7: 3 | BK7: 3 | BL7: 3 | BM7: 2 | BN7: 3 | BO7: 3 | BP7: 3 | BQ7: 2 | BR7: 3 | BS7: 3 | BT7: 2 | BU7: 3 | BV7: 2 | BW7: 3 | BX7: 3 | BY7: 3 | BZ7: 3 | CA7: 3 | CB7: 3 | CC7: 3 | CD7: 3 | CE7: 3 | CF7: 3 | CG7: 3 | CH7: 3 | CI7: 3 | CJ7: 3 | CK7: 3 | CL7: 3 | CM7: 3 | CN7: 3 | CO7: 3 | CP7: 3 | CQ7: 3 | CR7: 3 | CS7: 3 | CT7: 3 | CU7: 3 | CV7: 3 | CW7: 3 | CX7: 3 | CY7: 3 | CZ7: 3 | DA7: 3 | DB7: 3 | DC7: 2-3 horas | DH7: 3 | DI7: =CHAR(67+DH7*4) -> O | DJ7: PRG_03 | DK7: =O2 -> 4.18
A8: 46198.526 | B8: De 1 a 3 años | C8: 3 | D8: 4 | E8: Solo con supervisión | G8: 4 | H8: 3 | I8: 4 | J8: 3 | K8: 3 | L8: 5 | M8: 5 | N8: 4 | O8: 4 | P8: 4 | Q8: 1 | R8: 3 | S8: 5 | T8: 4 | U8: 5 | V8: 5 | W8: 2 | X8: 1 | Y8: 2 | Z8: 2 | AA8: 4 | AB8: 4 | AC8: 5 | AD8: 4 | AE8: 3 | AF8: 4 | AG8: 4 | AH8: 4 | AI8: 4 | AJ8: 4 | AK8: 3 | AL8: 5 | AM8: 3 | AN8: 1 | AO8: 3 | AP8: 2 | AQ8: 4 | AR8: 3 | AS8: 4 | AT8: 5 | AU8: 5 | AV8: 5 | AW8: 5 | AX8: 5 | AY8: 5 | AZ8: 4 | BA8: 5 | BB8: 5 | BC8: 4 | BD8: 3 | BE8: 3 | BF8: 4 | BG8: 3 | BH8: 2 | BI8: 3 | BJ8: 3 | BK8: 5 | BL8: 5 | BM8: 2 | BN8: 5 | BO8: 3 | BP8: 2 | BQ8: 4 | BR8: 4 | BS8: 4 | BT8: 2 | BU8: 3 | BV8: 3 | BW8: 5 | BX8: 5 | BY8: 4 | BZ8: 5 | CA8: 2 | CB8: 2 | CC8: 3 | CD8: 3 | CE8: 3 | CF8: 2 | CG8: 2 | CH8: 3 | CI8: 3 | CJ8: 4 | CK8: 3 | CL8: 5 | CM8: 3 | CN8: 2 | CO8: 5 | CP8: 4 | CQ8: 3 | CR8: 2 | CS8: 4 | CT8: 4 | CU8: 5 | CV8: 5 | CW8: 5 | CX8: 5 | CY8: 4 | CZ8: 4 | DA8: 3 | DB8: 4 | DC8: 4-5 horas | DH8: 4 | DI8: =CHAR(67+DH8*4) -> S | DJ8: PRG_04 | DK8: =S2 -> 4.23
A9: 46198.725 | B9: De 1 a 3 años | C9: 4 | D9: 5 | E9: Solo con supervisión | G9: 3 | H9: 3 | I9: 3 | J9: 3 | K9: 4 | L9: 4 | M9: 3 | N9: 4 | O9: 4 | P9: 5 | Q9: 4 | R9: 4 | S9: 3 | T9: 3 | U9: 3 | V9: 3 | W9: 3 | X9: 3 | Y9: 3 | Z9: 3 | AA9: 3 | AB9: 3 | AC9: 3 | AD9: 3 | AE9: 5 | AF9: 4 | AG9: 4 | AH9: 3 | AI9: 4 | AJ9: 4 | AK9: 4 | AL9: 4 | AM9: 3 | AN9: 3 | AO9: 3 | AP9: 3 | AQ9: 4 | AR9: 4 | AS9: 4 | AT9: 4 | AU9: 4 | AV9: 5 | AW9: 3 | AX9: 4 | AY9: 3 | AZ9: 3 | BA9: 3 | BB9: 3 | BC9: 5 | BD9: 5 | BE9: 5 | BF9: 5 | BG9: 3 | BH9: 3 | BI9: 3 | BJ9: 3 | BK9: 3 | BL9: 4 | BM9: 4 | BN9: 5 | BO9: 3 | BP9: 3 | BQ9: 3 | BR9: 3 | BS9: 4 | BT9: 4 | BU9: 4 | BV9: 4 | BW9: 4 | BX9: 4 | BY9: 4 | BZ9: 4 | CA9: 3 | CB9: 3 | CC9: 3 | CD9: 3 | CE9: 4 | CF9: 4 | CG9: 4 | CH9: 4 | CI9: 3 | CJ9: 3 | CK9: 3 | CL9: 3 | CM9: 3 | CN9: 3 | CO9: 3 | CP9: 3 | CQ9: 4 | CR9: 4 | CS9: 4 | CT9: 4 | CU9: 3 | CV9: 3 | CW9: 3 | CX9: 3 | CY9: 3 | CZ9: 3 | DA9: 3 | DB9: 3 | DC9: 2-3 horas | DH9: 5 | DI9: =CHAR(67+DH9*4) -> W | DJ9: PRG_05 | DK9: =W2 -> 3.25
A10: 46200.889 | B10: De 1 a 3 años | C10: 2 | D10: 3 | E10: Solo con supervisión | F10: El test por si solo no es relevante. La relevancia reside en que la prueba sea acorde a las competencias y contenidos abordados a lo largo del curso. Por qué tanto peso a las expresiones regulares? Por qué no hay más preguntas sobre el flujo de ejecución de un programa? Está bien balanceado el tipo de preguntas y dificultad? Y por último, es un examen de tipo test lo más adecuado para un módulo de programación? | G10: 4 | H10: 2 | I10: 3 | J10: 2 | K10: 4 | L10: 4 | M10: 4 | N10: 4 | O10: 4 | P10: 4 | Q10: 4 | R10: 4 | S10: 4 | T10: 4 | U10: 4 | V10: 4 | W10: 4 | X10: 2 | Y10: 4 | Z10: 4 | AA10: 4 | AB10: 4 | AC10: 4 | AD10: 4 | AE10: 4 | AF10: 4 | AG10: 4 | AH10: 4 | AI10: 4 | AJ10: 4 | AK10: 4 | AL10: 4 | AM10: 4 | AN10: 4 | AO10: 4 | AP10: 4 | AQ10: 4 | AR10: 4 | AS10: 4 | AT10: 4 | AU10: 4 | AV10: 4 | AW10: 4 | AX10: 4 | AY10: 4 | AZ10: 4 | BA10: 4 | BB10: 4 | BC10: 4 | BD10: 3 | BE10: 4 | BF10: 3 | BG10: 3 | BH10: 3 | BI10: 3 | BJ10: 2 | BK10: 4 | BL10: 4 | BM10: 4 | BN10: 4 | BO10: 3 | BP10: 3 | BQ10: 3 | BR10: 3 | BS10: 4 | BT10: 4 | BU10: 4 | BV10: 4 | BW10: 3 | BX10: 3 | BY10: 3 | BZ10: 3 | CA10: 2 | CB10: 2 | CC10: 2 | CD10: 2 | CE10: 1 | CF10: 1 | CG10: 1 | CH10: 1 | CI10: 4 | CJ10: 4 | CK10: 4 | CL10: 4 | CM10: 3 | CN10: 3 | CO10: 3 | CP10: 3 | CQ10: 4 | CR10: 4 | CS10: 4 | CT10: 4 | CU10: 4 | CV10: 4 | CW10: 4 | CX10: 4 | CY10: 4 | CZ10: 4 | DA10: 4 | DB10: 4 | DC10: 1 hora | DH10: 1 | DI10: =CHAR(61+DH10*4) -> A | DJ10: PRG_06 | DK10: =AA2 -> 3.93
A11: 46201.967 | B11: De 3 a 7 años | C11: 4 | D11: 4 | E11: Solo con supervisión | F11: La IA puede ayudar a generar preguntas, apuntes, ... pero hay que trabajar los promts adecuados para conseguir los objetivos deseados | G11: 4 | H11: 3 | I11: 4 | J11: 4 | K11: 4 | L11: 4 | M11: 4 | N11: 4 | O11: 4 | P11: 4 | Q11: 4 | R11: 4 | S11: 4 | T11: 4 | U11: 4 | V11: 4 | W11: 4 | X11: 4 | Y11: 4 | Z11: 4 | AA11: 4 | AB11: 4 | AC11: 4 | AD11: 4 | AE11: 4 | AF11: 4 | AG11: 4 | AH11: 4 | AI11: 4 | AJ11: 4 | AK11: 4 | AL11: 4 | AM11: 4 | AN11: 4 | AO11: 4 | AP11: 4 | AQ11: 4 | AR11: 4 | AS11: 4 | AT11: 4 | AU11: 4 | AV11: 4 | AW11: 4 | AX11: 4 | AY11: 4 | AZ11: 4 | BA11: 4 | BB11: 4 | BC11: 4 | BD11: 4 | BE11: 4 | BF11: 4 | BG11: 4 | BH11: 4 | BI11: 4 | BJ11: 4 | BK11: 3 | BL11: 3 | BM11: 3 | BN11: 4 | BO11: 4 | BP11: 4 | BQ11: 4 | BR11: 4 | BS11: 4 | BT11: 3 | BU11: 4 | BV11: 4 | BW11: 4 | BX11: 3 | BY11: 4 | BZ11: 4 | CA11: 4 | CB11: 4 | CC11: 4 | CD11: 4 | CE11: 4 | CF11: 3 | CG11: 4 | CH11: 4 | CI11: 4 | CJ11: 4 | CK11: 4 | CL11: 4 | CM11: 4 | CN11: 4 | CO11: 4 | CP11: 4 | CQ11: 4 | CR11: 3 | CS11: 4 | CT11: 4 | CU11: 4 | CV11: 3 | CW11: 4 | CX11: 4 | CY11: 4 | CZ11: 4 | DA11: 4 | DB11: 4 | DC11: 4-5 horas | DH11: 2 | DI11: =CHAR(61+DH11*4) -> E | DJ11: PRG_07 | DK11: =AE2 -> 3.85
A12: 46202.464 | B12: 1 año | C12: 5 | D12: 5 | E12: Solo con supervisión | G12: 5 | H12: 5 | I12: 5 | J12: 5 | K12: 5 | L12: 5 | M12: 5 | N12: 5 | O12: 5 | P12: 5 | Q12: 5 | R12: 5 | S12: 5 | T12: 5 | U12: 5 | V12: 5 | W12: 4 | X12: 4 | Y12: 4 | Z12: 4 | AA12: 5 | AB12: 5 | AC12: 5 | AD12: 5 | AE12: 4 | AF12: 4 | AG12: 4 | AH12: 4 | AI12: 4 | AJ12: 4 | AK12: 4 | AL12: 4 | AM12: 5 | AN12: 5 | AO12: 5 | AP12: 5 | AQ12: 4 | AR12: 5 | AS12: 4 | AT12: 4 | AU12: 5 | AV12: 5 | AW12: 5 | AX12: 5 | AY12: 4 | AZ12: 3 | BA12: 5 | BB12: 5 | BC12: 5 | BD12: 5 | BE12: 5 | BF12: 5 | BG12: 5 | BH12: 5 | BI12: 5 | BJ12: 5 | BK12: 4 | BL12: 3 | BM12: 4 | BN12: 5 | BO12: 4 | BP12: 5 | BQ12: 5 | BR12: 4 | BS12: 4 | BT12: 4 | BU12: 5 | BV12: 5 | BW12: 5 | BX12: 4 | BY12: 4 | BZ12: 4 | CA12: 5 | CB12: 5 | CC12: 5 | CD12: 5 | CE12: 5 | CF12: 5 | CG12: 5 | CH12: 5 | CI12: 5 | CJ12: 5 | CK12: 5 | CL12: 5 | CM12: 5 | CN12: 5 | CO12: 5 | CP12: 5 | CQ12: 4 | CR12: 5 | CS12: 5 | CT12: 5 | CU12: 5 | CV12: 3 | CW12: 5 | CX12: 5 | CY12: 4 | CZ12: 4 | DA12: 4 | DB12: 4 | DC12: 4-5 horas | DH12: 3 | DI12: =CHAR(61+DH12*4) -> I | DJ12: PRG_08 | DK12: =AI2 -> 3.98
A13: 46202.502 | B13: 1 año | C13: 1 | D13: 2 | E13: Solo con supervisión | G13: 3 | H13: 4 | I13: 3 | J13: 2 | K13: 4 | L13: 4 | M13: 3 | N13: 4 | O13: 5 | P13: 5 | Q13: 4 | R13: 5 | S13: 5 | T13: 5 | U13: 5 | V13: 3 | W13: 3 | X13: 3 | Y13: 2 | Z13: 2 | AA13: 3 | AB13: 3 | AC13: 3 | AD13: 3 | AE13: 4 | AF13: 3 | AG13: 2 | AH13: 3 | AI13: 4 | AJ13: 4 | AK13: 3 | AL13: 4 | AM13: 3 | AN13: 3 | AO13: 3 | AP13: 4 | AQ13: 5 | AR13: 4 | AS13: 5 | AT13: 5 | AU13: 4 | AV13: 4 | AW13: 3 | AX13: 4 | AY13: 5 | AZ13: 5 | BA13: 4 | BB13: 4 | BC13: 3 | BD13: 3 | BE13: 3 | BF13: 2 | BG13: 4 | BH13: 3 | BI13: 3 | BJ13: 3 | BK13: 3 | BL13: 2 | BM13: 3 | BN13: 2 | BO13: 3 | BP13: 2 | BQ13: 3 | BR13: 2 | BS13: 2 | BT13: 2 | BU13: 2 | BV13: 2 | BW13: 5 | BX13: 4 | BY13: 4 | BZ13: 5 | CA13: 3 | CB13: 3 | CC13: 3 | CD13: 3 | CE13: 4 | CF13: 2 | CG13: 3 | CH13: 3 | CI13: 3 | CJ13: 3 | CK13: 3 | CL13: 3 | CM13: 3 | CN13: 3 | CO13: 3 | CP13: 3 | CQ13: 5 | CR13: 4 | CS13: 5 | CT13: 5 | CU13: 5 | CV13: 3 | CW13: 3 | CX13: 4 | CY13: 3 | CZ13: 3 | DA13: 3 | DB13: 3 | DC13: 2-3 horas | DH13: 4 | DI13: =CHAR(61+DH13*4) -> M | DJ13: PRG_09
A14: 46203.938 | B14: 1 año | C14: 4 | D14: 4 | E14: Solo con supervisión | F14: La IA no es perfecta, pero tampoco lo somos los docentes. En la elaboración de test, la combinación de criterio docente e IA permite reducir errores y aligerar notablemente la carga de trabajo. En el futuro, es posible que el papel humano en estas tareas sea cada vez menor. | G14: 5 | H14: 4 | I14: 4 | J14: 5 | K14: 5 | L14: 3 | M14: 3 | N14: 4 | O14: 5 | P14: 3 | Q14: 4 | R14: 5 | S14: 5 | T14: 3 | U14: 5 | V14: 5 | W14: 4 | X14: 3 | Y14: 3 | Z14: 3 | AA14: 5 | AB14: 3 | AC14: 4 | AD14: 5 | AE14: 5 | AF14: 3 | AG14: 4 | AH14: 4 | AI14: 5 | AJ14: 3 | AK14: 4 | AL14: 5 | AM14: 5 | AN14: 3 | AO14: 3 | AP14: 3 | AQ14: 5 | AR14: 4 | AS14: 5 | AT14: 5 | AU14: 5 | AV14: 3 | AW14: 4 | AX14: 5 | AY14: 5 | AZ14: 4 | BA14: 4 | BB14: 5 | BC14: 5 | BD14: 4 | BE14: 4 | BF14: 5 | BG14: 3 | BH14: 3 | BI14: 4 | BJ14: 3 | BK14: 5 | BL14: 3 | BM14: 4 | BN14: 5 | BO14: 5 | BP14: 4 | BQ14: 5 | BR14: 5 | BS14: 5 | BT14: 3 | BU14: 3 | BV14: 4 | BW14: 5 | BX14: 4 | BY14: 5 | BZ14: 5 | CA14: 5 | CB14: 3 | CC14: 3 | CD14: 5 | CE14: 5 | CF14: 5 | CG14: 5 | CH14: 5 | CI14: 5 | CJ14: 4 | CK14: 4 | CL14: 5 | CM14: 5 | CN14: 4 | CO14: 4 | CP14: 5 | CQ14: 5 | CR14: 3 | CS14: 4 | CT14: 5 | CU14: 5 | CV14: 3 | CW14: 4 | CX14: 5 | CY14: 5 | CZ14: 4 | DA14: 4 | DB14: 5 | DC14: 4-5 horas
DH15: 6 | DI15: =CHAR(61+DH15*4) -> U | DJ15: PRG_11
DH16: 12 | DI16: =CHAR(70+DH16) -> R | DJ16: PRG_12
DH17: 13 | DI17: =CHAR(70+DH17) -> S | DJ17: PRG_13
DH18: 14 | DI18: =CHAR(70+DH18) -> T | DJ18: PRG_14
DH19: 15 | DI19: =CHAR(70+DH19) -> U | DJ19: PRG_15
DH20: 16 | DI20: =CHAR(70+DH20) -> V | DJ20: PRG_16
DH21: 17 | DI21: =CHAR(70+DH21) -> W | DJ21: PRG_17
H22: =((COLUMN()-8)*4)+7 -> 7 | I22: =((COLUMN()-8)*4)+7 -> 11 | J22: =((COLUMN()-8)*4)+7 -> 15 | K22: =((COLUMN()-8)*4)+7 -> 19 | L22: =((COLUMN()-8)*4)+7 -> 23 | M22: =((COLUMN()-8)*4)+7 -> 27 | N22: =((COLUMN()-8)*4)+7 -> 31 | O22: =((COLUMN()-8)*4)+7 -> 35 | ... AF22: =((COLUMN()-8)*4)+7 -> 103
E23: Claridad técnica | H23: {=INDEX($A:$FF,3,H$22)} -> 3.8 | I23: {=INDEX($A:$FF,3,I$22)} -> 4.2 | J23: {=INDEX($A:$FF,3,J$22)} -> 4.3 | K23: {=INDEX($A:$FF,3,K$22)} -> 4.4 | L23: {=INDEX($A:$FF,3,L$22)} -> 3.7 | M23: {=INDEX($A:$FF,3,M$22)} -> 4 | N23: {=INDEX($A:$FF,3,N$22)} -> 4 | O23: {=INDEX($A:$FF,3,O$22)} -> 4.2 | ... AF23: {=INDEX($A:$FF,3,AF$22)} -> 4
E24: Nivel de dificultad adecuado | H24: {=INDEX($A:$FF,3,H$22+1)} -> 3.2 | I24: {=INDEX($A:$FF,3,I$22+1)} -> 4.2 | J24: {=INDEX($A:$FF,3,J$22+1)} -> 4.3 | K24: {=INDEX($A:$FF,3,K$22+1)} -> 4.1 | L24: {=INDEX($A:$FF,3,L$22+1)} -> 3 | M24: {=INDEX($A:$FF,3,M$22+1)} -> 3.7 | N24: {=INDEX($A:$FF,3,N$22+1)} -> 3.8 | O24: {=INDEX($A:$FF,3,O$22+1)} -> 3.7 | ... AF24: {=INDEX($A:$FF,3,AF$22+1)} -> 3.9
E25: Calidad de los distractores | H25: {=INDEX($A:$FF,3,H$22+2)} -> 3.7 | I25: {=INDEX($A:$FF,3,I$22+2)} -> 3.7 | J25: {=INDEX($A:$FF,3,J$22+2)} -> 3.9 | K25: {=INDEX($A:$FF,3,K$22+2)} -> 4.3 | L25: {=INDEX($A:$FF,3,L$22+2)} -> 3.1 | M25: {=INDEX($A:$FF,3,M$22+2)} -> 3.9 | N25: {=INDEX($A:$FF,3,N$22+2)} -> 3.9 | O25: {=INDEX($A:$FF,3,O$22+2)} -> 3.8 | ... AF25: {=INDEX($A:$FF,3,AF$22+2)} -> 3.8
E26: Validez pedagógica | H26: {=INDEX($A:$FF,3,H$22+3)} -> 3.4 | I26: {=INDEX($A:$FF,3,I$22+3)} -> 4.1 | J26: {=INDEX($A:$FF,3,J$22+3)} -> 4.2 | K26: {=INDEX($A:$FF,3,K$22+3)} -> 4.1 | L26: {=INDEX($A:$FF,3,L$22+3)} -> 3.2 | M26: {=INDEX($A:$FF,3,M$22+3)} -> 4.1 | N26: {=INDEX($A:$FF,3,N$22+3)} -> 3.7 | O26: {=INDEX($A:$FF,3,O$22+3)} -> 4.2 | ... AF26: {=INDEX($A:$FF,3,AF$22+3)} -> 4
E27: Promedio | H27: =AVERAGE(H23:H26) -> 3.525 | I27: =AVERAGE(I23:I26) -> 4.05 | J27: =AVERAGE(J23:J26) -> 4.175 | K27: =AVERAGE(K23:K26) -> 4.225 | L27: =AVERAGE(L23:L26) -> 3.25 | M27: =AVERAGE(M23:M26) -> 3.925 | N27: =AVERAGE(N23:N26) -> 3.85 | O27: =AVERAGE(O23:O26) -> 3.975 | ... AF27: =AVERAGE(AF23:AF26) -> 3.925
H28: 1 | I28: 2 | J28: 3 | K28: 4 | L28: 5 | M28: 6 | N28: 7 | O28: 8 | P28: 9 | Q28: 10 | R28: 11 | S28: 12 | T28: 13 | U28: 14 | V28: 15 | W28: 16 | X28: 17 | Y28: 18 | Z28: 19 | AA28: 20 | AB28: 21 | AC28: 22 | AD28: 23 | AE28: 24 | AF28: 25
DH29: 25 | DI29: =CHAR(70+DH29) -> _ | DJ29: PRG_25
H31: =E23 -> Claridad técnica | I31: =E24 -> Nivel de dificultad adecuado | J31: =E25 -> Calidad de los distractores | K31: =E26 -> Validez pedagógica | L31: Media
G32: Q_01 | H32: {=TRANSPOSE(H23:AF23)} -> 3.8 | I32: {=TRANSPOSE(H24:AF24)} -> 3.2 | J32: {=TRANSPOSE(H25:AF25)} -> 3.7 | K32: {=TRANSPOSE(H26:AF26)} -> 3.4 | L32: {=TRANSPOSE(H27:AF27)} -> 3.525
G33: Q_02 | H33: 4.2 | I33: 4.2 | J33: 3.7 | K33: 4.1 | L33: 4.05
G34: Q_03 | H34: 4.3 | I34: 4.3 | J34: 3.9 | K34: 4.2 | L34: 4.175
G35: Q_04 | H35: 4.4 | I35: 4.1 | J35: 4.3 | K35: 4.1 | L35: 4.225
G36: Q_05 | H36: 3.7 | I36: 3 | J36: 3.1 | K36: 3.2 | L36: 3.25
G37: Q_06 | H37: 4 | I37: 3.7 | J37: 3.9 | K37: 4.1 | L37: 3.925
G38: Q_07 | H38: 4 | I38: 3.8 | J38: 3.9 | K38: 3.7 | L38: 3.85
G39: Q_08 | H39: 4.2 | I39: 3.7 | J39: 3.8 | K39: 4.2 | L39: 3.975
G40: Q_09 | H40: 4.1 | I40: 3.4 | J40: 3.7 | K40: 3.7 | L40: 3.725
G41: Q_10 | H41: 4.4 | I41: 4 | J41: 4.3 | K41: 4.4 | L41: 4.275
...

Sheet 1Year
G1: PRG_01 | K1: PRG_02 | O1: PRG_03 | S1: PRG_04 | W1: PRG_05 | AA1: PRG_06 | AE1: PRG_07 | AI1: PRG_08 | AM1: PRG_09 | AQ1: PRG_10 | AU1: PRG_11 | AY1: PRG_12 | BC1: PRG_13 | BG1: PRG_14 | BK1: PRG_15 | BO1: PRG_16 | BS1: PRG_17 | BW1: PRG_18 | CA1: PRG_19 | CE1: PRG_20 | CI1: PRG_21 | CM1: PRG_22 | CQ1: PRG_23 | CU1: PRG_24 | CY1: PRG_25
F2: =ROUND(AVERAGE(G3:DB3),2) -> 3.8 | G2: =ROUND(AVERAGE(G3:J3),2) -> 3.88 | K2: =ROUND(AVERAGE(K3:N3),2) -> 3.81 | O2: =ROUND(AVERAGE(O3:R3),2) -> 4.13 | S2: =ROUND(AVERAGE(S3:V3),2) -> 4.13 | W2: =ROUND(AVERAGE(W3:Z3),2) -> 3.06 | AA2: =ROUND(AVERAGE(AA3:AD3),2) -> 3.75 | AE2: =ROUND(AVERAGE(AE3:AH3),2) -> 3.5 | AI2: =ROUND(AVERAGE(AI3:AL3),2) -> 3.75 | AM2: =ROUND(AVERAGE(AM3:AP3),2) -> 3.75 | AQ2: =ROUND(AVERAGE(AQ3:AT3),2) -> 4.25 | AU2: =ROUND(AVERAGE(AU3:AX3),2) -> 4 | AY2: =ROUND(AVERAGE(AY3:BB3),2) -> 4.06 | BC2: =ROUND(AVERAGE(BC3:BF3),2) -> 3.81 | BG2: =ROUND(AVERAGE(BG3:BJ3),2) -> 3.63 | BK2: =ROUND(AVERAGE(BK3:BN3),2) -> 3.38 | BO2: =ROUND(AVERAGE(BO3:BR3),2) -> 3.63 | BS2: =ROUND(AVERAGE(BS3:BV3),2) -> 3.19 | BW2: =ROUND(AVERAGE(BW3:BZ3),2) -> 4.13 | CA2: =ROUND(AVERAGE(CA3:CD3),2) -> 3.75 | CE2: =ROUND(AVERAGE(CE3:CH3),2) -> 4 | CI2: =ROUND(AVERAGE(CI3:CL3),2) -> 3.88 | CM2: =ROUND(AVERAGE(CM3:CP3),2) -> 3.88 | CQ2: =ROUND(AVERAGE(CQ3:CT3),2) -> 4.19 | CU2: =ROUND(AVERAGE(CU3:CX3),2) -> 3.88 | CY2: =ROUND(AVERAGE(CY3:DB3),2) -> 3.63
C3: =ROUND(AVERAGE(C5:C51),2) -> 3.75 | D3: =ROUND(AVERAGE(D5:D51),2) -> 4 | G3: =ROUND(AVERAGE(G5:G20),2) -> 4 | H3: =ROUND(AVERAGE(H5:H20),2) -> 4 | I3: =ROUND(AVERAGE(I5:I20),2) -> 3.75 | J3: =ROUND(AVERAGE(J5:J20),2) -> 3.75 | K3: =ROUND(AVERAGE(K5:K20),2) -> 4.25 | L3: =ROUND(AVERAGE(L5:L20),2) -> 3.75 | M3: =ROUND(AVERAGE(M5:M20),2) -> 3.25 | N3: =ROUND(AVERAGE(N5:N20),2) -> 4 | ... DB3: =ROUND(AVERAGE(DB5:DB20),2) -> 3.75
B4: ¿Cuantos años de experiencia tienes enseñando Python? | C4: ¿Con qué frecuencia utiliza modelos de IA para apoyarte en la práctica docente? | D4: ¿Cual es tu actitud hacia el uso de la IA en educación? | E4: ¿Consideras que la IA es capaz de sustituir la creación manual de exámenes de programación a corto plazo? | F4: Espacio libre. Deja los comentarios que creas oportunos. | G4: Pregunta 1 [Claridad técnica] | H4: Pregunta 1 [Nivel de dificultad adecuado] | I4: Pregunta 1 [Calidad de los distractores] | J4: Pregunta 1 [Validez pedagógica] | K4: Pregunta 2 [Claridad técnica] | L4: Pregunta 2 [Nivel de dificultad adecuado] | M4: Pregunta 2 [Calidad de los distractores] | N4: Pregunta 2 [Validez pedagógica] | O4: Pregunta 3 [Claridad técnica] | P4: Pregunta 3 [Nivel de dificultad adecuado] | Q4: Pregunta 3 [Calidad de los distractores] | R4: Pregunta 3 [Validez pedagógica] | S4: Pregunta 4 [Claridad técnica] | T4: Pregunta 4 [Nivel de dificultad adecuado] | U4: Pregunta 4 [Calidad de los distractores] | V4: Pregunta 4 [Validez pedagógica] | W4: Pregunta 5 [Claridad técnica] | X4: Pregunta 5 [Nivel de dificultad adecuado] | Y4: Pregunta 5 [Calidad de los distractores] | Z4: Pregunta 5 [Validez pedagógica] | AA4: Pregunta 6 [Claridad técnica] | AB4: Pregunta 6 [Nivel de dificultad adecuado] | AC4: Pregunta 6 [Calidad de los distractores] | AD4: Pregunta 6 [Validez pedagógica] | AE4: Pregunta 7 [Claridad técnica] | AF4: Pregunta 7 [Nivel de dificultad adecuado] | AG4: Pregunta 7 [Calidad de los distractores] | AH4: Pregunta 7 [Validez pedagógica] | AI4: Pregunta 8 [Claridad técnica] | AJ4: Pregunta 8 [Nivel de dificultad adecuado] | AK4: Pregunta 8 [Calidad de los distractores] | AL4: Pregunta 8 [Validez pedagógica] | AM4: Pregunta 9 [Claridad técnica] | AN4: Pregunta 9 [Nivel de dificultad adecuado] | AO4: Pregunta 9 [Calidad de los distractores] | AP4: Pregunta 9 [Validez pedagógica] | AQ4: Pregunta 10 [Claridad técnica] | AR4: Pregunta 10 [Nivel de dificultad adecuado] | AS4: Pregunta 10 [Calidad de los distractores] | AT4: Pregunta 10 [Validez pedagógica] | AU4: Pregunta 11 [Claridad técnica] | AV4: Pregunta 11 [Nivel de dificultad adecuado] | AW4: Pregunta 11 [Calidad de los distractores] | AX4: Pregunta 11 [Validez pedagógica] | AY4: Pregunta 12 [Claridad técnica] | AZ4: Pregunta 12 [Nivel de dificultad adecuado] | BA4: Pregunta 12 [Calidad de los distractores] | BB4: Pregunta 12 [Validez pedagógica] | BC4: Pregunta 13 [Claridad técnica] | BD4: Pregunta 13 [Nivel de dificultad adecuado] | BE4: Pregunta 13 [Calidad de los distractores] | BF4: Pregunta 13 [Validez pedagógica] | BG4: Pregunta 14 [Claridad técnica] | BH4: Pregunta 14 [Nivel de dificultad adecuado] | BI4: Pregunta 14 [Calidad de los distractores] | BJ4: Pregunta 14 [Validez pedagógica] | BK4: Pregunta 15 [Claridad técnica] | BL4: Pregunta 15 [Nivel de dificultad adecuado] | BM4: Pregunta 15 [Calidad de los distractores] | BN4: Pregunta 15 [Validez pedagógica] | BO4: Pregunta 16 [Claridad técnica] | BP4: Pregunta 16 [Nivel de dificultad adecuado] | BQ4: Pregunta 16 [Calidad de los distractores] | BR4: Pregunta 16 [Validez pedagógica] | BS4: Pregunta 17 [Claridad técnica] | BT4: Pregunta 17 [Nivel de dificultad adecuado] | BU4: Pregunta 17 [Calidad de los distractores] | BV4: Pregunta 17 [Validez pedagógica] | BW4: Pregunta 18 [Claridad técnica] | BX4: Pregunta 18 [Nivel de dificultad adecuado] | BY4: Pregunta 18 [Calidad de los distractores] | BZ4: Pregunta 18 [Validez pedagógica] | CA4: Pregunta 19 [Claridad técnica] | CB4: Pregunta 19 [Nivel de dificultad adecuado] | CC4: Pregunta 19 [Calidad de los distractores] | CD4: Pregunta 19 [Validez pedagógica] | CE4: Pregunta 20 [Claridad técnica] | CF4: Pregunta 20 [Nivel de dificultad adecuado] | CG4: Pregunta 20 [Calidad de los distractores] | CH4: Pregunta 20 [Validez pedagógica] | CI4: Pregunta 21 [Claridad técnica] | CJ4: Pregunta 21 [Nivel de dificultad adecuado] | CK4: Pregunta 21 [Calidad de los distractores] | CL4: Pregunta 21 [Validez pedagógica] | CM4: Pregunta 22 [Claridad técnica] | CN4: Pregunta 22 [Nivel de dificultad adecuado] | CO4: Pregunta 22 [Calidad de los distractores] | CP4: Pregunta 22 [Validez pedagógica] | CQ4: Pregunta 23 [Claridad técnica] | CR4: Pregunta 23 [Nivel de dificultad adecuado] | CS4: Pregunta 23 [Calidad de los distractores] | CT4: Pregunta 23 [Validez pedagógica] | CU4: Pregunta 24 [Claridad técnica] | CV4: Pregunta 24 [Nivel de dificultad adecuado] | CW4: Pregunta 24 [Calidad de los distractores] | CX4: Pregunta 24 [Validez pedagógica] | CY4: Pregunta 25 [Claridad técnica] | CZ4: Pregunta 25 [Nivel de dificultad adecuado] | DA4: Pregunta 25 [Calidad de los distractores] | DB4: Pregunta 25 [Validez pedagógica] | DC4: ¿Cuanto tiempo crees que te llevaría hacer un examen como este de 25 pegruntas sin ayuda de la IA?
B5: {=_xlfn._xlws.FILTER(Resp!B:DE, Resp!B:B="1 año", "No hay datos")} -> 1 año | C5: 5 | D5: 5 | E5: Solo con supervisión | F5: 0 | G5: 3 | H5: 3 | I5: 3 | J5: 3 | K5: 3 | L5: 3 | M5: 2 | N5: 3 | O5: 2 | P5: 3 | Q5: 3 | R5: 2 | S5: 3 | T5: 3 | U5: 2 | V5: 2 | W5: 3 | X5: 3 | Y5: 2 | Z5: 2 | AA5: 3 | AB5: 3 | AC5: 2 | AD5: 3 | AE5: 4 | AF5: 2 | AG5: 3 | AH5: 3 | AI5: 3 | AJ5: 3 | AK5: 3 | AL5: 3 | AM5: 4 | AN5: 3 | AO5: 3 | AP5: 3 | AQ5: 4 | AR5: 2 | AS5: 4 | AT5: 3 | AU5: 3 | AV5: 3 | AW5: 3 | AX5: 3 | AY5: 3 | AZ5: 3 | BA5: 3 | BB5: 3 | BC5: 3 | BD5: 3 | BE5: 3 | BF5: 3 | BG5: 4 | BH5: 3 | BI5: 2 | BJ5: 3 | BK5: 3 | BL5: 3 | BM5: 2 | BN5: 3 | BO5: 3 | BP5: 3 | BQ5: 2 | BR5: 3 | BS5: 3 | BT5: 2 | BU5: 3 | BV5: 2 | BW5: 3 | BX5: 3 | BY5: 3 | BZ5: 3 | CA5: 3 | CB5: 3 | CC5: 3 | CD5: 3 | CE5: 3 | CF5: 3 | CG5: 3 | CH5: 3 | CI5: 3 | CJ5: 3 | CK5: 3 | CL5: 3 | CM5: 3 | CN5: 3 | CO5: 3 | CP5: 3 | CQ5: 3 | CR5: 3 | CS5: 3 | CT5: 3 | CU5: 3 | CV5: 3 | CW5: 3 | CX5: 3 | CY5: 3 | CZ5: 3 | DA5: 3 | DB5: 3 | DC5: 2-3 horas | DD5: 0 | DE5: 0
B6: 1 año | C6: 5 | D6: 5 | E6: Solo con supervisión | F6: 0 | G6: 5 | H6: 5 | I6: 5 | J6: 5 | K6: 5 | L6: 5 | M6: 5 | N6: 5 | O6: 5 | P6: 5 | Q6: 5 | R6: 5 | S6: 5 | T6: 5 | U6: 5 | V6: 5 | W6: 4 | X6: 4 | Y6: 4 | Z6: 4 | AA6: 5 | AB6: 5 | AC6: 5 | AD6: 5 | AE6: 4 | AF6: 4 | AG6: 4 | AH6: 4 | AI6: 4 | AJ6: 4 | AK6: 4 | AL6: 4 | AM6: 5 | AN6: 5 | AO6: 5 | AP6: 5 | AQ6: 4 | AR6: 5 | AS6: 4 | AT6: 4 | AU6: 5 | AV6: 5 | AW6: 5 | AX6: 5 | AY6: 4 | AZ6: 3 | BA6: 5 | BB6: 5 | BC6: 5 | BD6: 5 | BE6: 5 | BF6: 5 | BG6: 5 | BH6: 5 | BI6: 5 | BJ6: 5 | BK6: 4 | BL6: 3 | BM6: 4 | BN6: 5 | BO6: 4 | BP6: 5 | BQ6: 5 | BR6: 4 | BS6: 4 | BT6: 4 | BU6: 5 | BV6: 5 | BW6: 5 | BX6: 4 | BY6: 4 | BZ6: 4 | CA6: 5 | CB6: 5 | CC6: 5 | CD6: 5 | CE6: 5 | CF6: 5 | CG6: 5 | CH6: 5 | CI6: 5 | CJ6: 5 | CK6: 5 | CL6: 5 | CM6: 5 | CN6: 5 | CO6: 5 | CP6: 5 | CQ6: 4 | CR6: 5 | CS6: 5 | CT6: 5 | CU6: 5 | CV6: 3 | CW6: 5 | CX6: 5 | CY6: 4 | CZ6: 4 | DA6: 4 | DB6: 4 | DC6: 4-5 horas | DD6: 0 | DE6: 0
B7: 1 año | C7: 1 | D7: 2 | E7: Solo con supervisión | F7: 0 | G7: 3 | H7: 4 | I7: 3 | J7: 2 | K7: 4 | L7: 4 | M7: 3 | N7: 4 | O7: 5 | P7: 5 | Q7: 4 | R7: 5 | S7: 5 | T7: 5 | U7: 5 | V7: 3 | W7: 3 | X7: 3 | Y7: 2 | Z7: 2 | AA7: 3 | AB7: 3 | AC7: 3 | AD7: 3 | AE7: 4 | AF7: 3 | AG7: 2 | AH7: 3 | AI7: 4 | AJ7: 4 | AK7: 3 | AL7: 4 | AM7: 3 | AN7: 3 | AO7: 3 | AP7: 4 | AQ7: 5 | AR7: 4 | AS7: 5 | AT7: 5 | AU7: 4 | AV7: 4 | AW7: 3 | AX7: 4 | AY7: 5 | AZ7: 5 | BA7: 4 | BB7: 4 | BC7: 3 | BD7: 3 | BE7: 3 | BF7: 2 | BG7: 4 | BH7: 3 | BI7: 3 | BJ7: 3 | BK7: 3 | BL7: 2 | BM7: 3 | BN7: 2 | BO7: 3 | BP7: 2 | BQ7: 3 | BR7: 2 | BS7: 2 | BT7: 2 | BU7: 2 | BV7: 2 | BW7: 5 | BX7: 4 | BY7: 4 | BZ7: 5 | CA7: 3 | CB7: 3 | CC7: 3 | CD7: 3 | CE7: 4 | CF7: 2 | CG7: 3 | CH7: 3 | CI7: 3 | CJ7: 3 | CK7: 3 | CL7: 3 | CM7: 3 | CN7: 3 | CO7: 3 | CP7: 3 | CQ7: 5 | CR7: 4 | CS7: 5 | CT7: 5 | CU7: 5 | CV7: 3 | CW7: 3 | CX7: 4 | CY7: 3 | CZ7: 3 | DA7: 3 | DB7: 3 | DC7: 2-3 horas | DD7: 0 | DE7: 0
B8: 1 año | C8: 4 | D8: 4 | E8: Solo con supervisión | F8: La IA no es perfecta, pero tampoco lo somos los docentes. En la elaboración de test, la combinación de criterio docente e IA permite reducir errores y aligerar notablemente la carga de trabajo. En el futuro, es posible que el papel humano en estas tareas sea cada vez menor. | G8: 5 | H8: 4 | I8: 4 | J8: 5 | K8: 5 | L8: 3 | M8: 3 | N8: 4 | O8: 5 | P8: 3 | Q8: 4 | R8: 5 | S8: 5 | T8: 3 | U8: 5 | V8: 5 | W8: 4 | X8: 3 | Y8: 3 | Z8: 3 | AA8: 5 | AB8: 3 | AC8: 4 | AD8: 5 | AE8: 5 | AF8: 3 | AG8: 4 | AH8: 4 | AI8: 5 | AJ8: 3 | AK8: 4 | AL8: 5 | AM8: 5 | AN8: 3 | AO8: 3 | AP8: 3 | AQ8: 5 | AR8: 4 | AS8: 5 | AT8: 5 | AU8: 5 | AV8: 3 | AW8: 4 | AX8: 5 | AY8: 5 | AZ8: 4 | BA8: 4 | BB8: 5 | BC8: 5 | BD8: 4 | BE8: 4 | BF8: 5 | BG8: 3 | BH8: 3 | BI8: 4 | BJ8: 3 | BK8: 5 | BL8: 3 | BM8: 4 | BN8: 5 | BO8: 5 | BP8: 4 | BQ8: 5 | BR8: 5 | BS8: 5 | BT8: 3 | BU8: 3 | BV8: 4 | BW8: 5 | BX8: 4 | BY8: 5 | BZ8: 5 | CA8: 5 | CB8: 3 | CC8: 3 | CD8: 5 | CE8: 5 | CF8: 5 | CG8: 5 | CH8: 5 | CI8: 5 | CJ8: 4 | CK8: 4 | CL8: 5 | CM8: 5 | CN8: 4 | CO8: 4 | CP8: 5 | CQ8: 5 | CR8: 3 | CS8: 4 | CT8: 5 | CU8: 5 | CV8: 3 | CW8: 4 | CX8: 5 | CY8: 5 | CZ8: 4 | DA8: 4 | DB8: 5 | DC8: 4-5 horas | DD8: 0 | DE8: 0
H22: =((COLUMN()-8)*4)+7 -> 7 | I22: =((COLUMN()-8)*4)+7 -> 11 | J22: =((COLUMN()-8)*4)+7 -> 15 | K22: =((COLUMN()-8)*4)+7 -> 19 | L22: =((COLUMN()-8)*4)+7 -> 23 | M22: =((COLUMN()-8)*4)+7 -> 27 | N22: =((COLUMN()-8)*4)+7 -> 31 | O22: =((COLUMN()-8)*4)+7 -> 35 | ... AF22: =((COLUMN()-8)*4)+7 -> 103
E23: Claridad técnica | H23: {=INDEX($A:$FF,3,H$22)} -> 4 | I23: {=INDEX($A:$FF,3,I$22)} -> 4.25 | J23: {=INDEX($A:$FF,3,J$22)} -> 4.25 | K23: {=INDEX($A:$FF,3,K$22)} -> 4.5 | L23: {=INDEX($A:$FF,3,L$22)} -> 3.5 | M23: {=INDEX($A:$FF,3,M$22)} -> 4 | N23: {=INDEX($A:$FF,3,N$22)} -> 4.25 | O23: {=INDEX($A:$FF,3,O$22)} -> 4 | ... AF23: {=INDEX($A:$FF,3,AF$22)} -> 3.75
E24: Nivel de dificultad adecuado | H24: {=INDEX($A:$FF,3,H$22+1)} -> 4 | I24: {=INDEX($A:$FF,3,I$22+1)} -> 3.75 | J24: {=INDEX($A:$FF,3,J$22+1)} -> 4 | K24: {=INDEX($A:$FF,3,K$22+1)} -> 4 | L24: {=INDEX($A:$FF,3,L$22+1)} -> 3.25 | M24: {=INDEX($A:$FF,3,M$22+1)} -> 3.5 | N24: {=INDEX($A:$FF,3,N$22+1)} -> 3 | O24: {=INDEX($A:$FF,3,O$22+1)} -> 3.5 | ... AF24: {=INDEX($A:$FF,3,AF$22+1)} -> 3.5
E25: Calidad de los distractores | H25: {=INDEX($A:$FF,3,H$22+2)} -> 3.75 | I25: {=INDEX($A:$FF,3,I$22+2)} -> 3.25 | J25: {=INDEX($A:$FF,3,J$22+2)} -> 4 | K25: {=INDEX($A:$FF,3,K$22+2)} -> 4.25 | L25: {=INDEX($A:$FF,3,L$22+2)} -> 2.75 | M25: {=INDEX($A:$FF,3,M$22+2)} -> 3.5 | N25: {=INDEX($A:$FF,3,N$22+2)} -> 3.25 | O25: {=INDEX($A:$FF,3,O$22+2)} -> 3.5 | ... AF25: {=INDEX($A:$FF,3,AF$22+2)} -> 3.5
E26: Validez pedagógica | H26: {=INDEX($A:$FF,3,H$22+3)} -> 3.75 | I26: {=INDEX($A:$FF,3,I$22+3)} -> 4 | J26: {=INDEX($A:$FF,3,J$22+3)} -> 4.25 | K26: {=INDEX($A:$FF,3,K$22+3)} -> 3.75 | L26: {=INDEX($A:$FF,3,L$22+3)} -> 2.75 | M26: {=INDEX($A:$FF,3,M$22+3)} -> 4 | N26: {=INDEX($A:$FF,3,N$22+3)} -> 3.5 | O26: {=INDEX($A:$FF,3,O$22+3)} -> 4 | ... AF26: {=INDEX($A:$FF,3,AF$22+3)} -> 3.75
E27: Promedio | H27: =AVERAGE(H23:H26) -> 3.875 | I27: =AVERAGE(I23:I26) -> 3.8125 | J27: =AVERAGE(J23:J26) -> 4.125 | K27: =AVERAGE(K23:K26) -> 4.125 | L27: =AVERAGE(L23:L26) -> 3.0625 | M27: =AVERAGE(M23:M26) -> 3.75 | N27: =AVERAGE(N23:N26) -> 3.5 | O27: =AVERAGE(O23:O26) -> 3.75 | ... AF27: =AVERAGE(AF23:AF26) -> 3.625
H28: 1 | I28: 2 | J28: 3 | K28: 4 | L28: 5 | M28: 6 | N28: 7 | O28: 8 | P28: 9 | Q28: 10 | R28: 11 | S28: 12 | T28: 13 | U28: 14 | V28: 15 | W28: 16 | X28: 17 | Y28: 18 | Z28: 19 | AA28: 20 | AB28: 21 | AC28: 22 | AD28: 23 | AE28: 24 | AF28: 25
H31: =E23 -> Claridad técnica | I31: =E24 -> Nivel de dificultad adecuado | J31: =E25 -> Calidad de los distractores | K31: =E26 -> Validez pedagógica | L31: Media
G32: Q_01 | H32: {=TRANSPOSE(H23:AF23)} -> 4 | I32: {=TRANSPOSE(H24:AF24)} -> 4 | J32: {=TRANSPOSE(H25:AF25)} -> 3.75 | K32: {=TRANSPOSE(H26:AF26)} -> 3.75 | L32: {=TRANSPOSE(H27:AF27)} -> 3.875
G33: Q_02 | H33: 4.25 | I33: 3.75 | J33: 3.25 | K33: 4 | L33: 3.8125
G34: Q_03 | H34: 4.25 | I34: 4 | J34: 4 | K34: 4.25 | L34: 4.125
G35: Q_04 | H35: 4.5 | I35: 4 | J35: 4.25 | K35: 3.75 | L35: 4.125
G36: Q_05 | H36: 3.5 | I36: 3.25 | J36: 2.75 | K36: 2.75 | L36: 3.0625
G37: Q_06 | H37: 4 | I37: 3.5 | J37: 3.5 | K37: 4 | L37: 3.75
G38: Q_07 | H38: 4.25 | I38: 3 | J38: 3.25 | K38: 3.5 | L38: 3.5
G39: Q_08 | H39: 4 | I39: 3.5 | J39: 3.5 | K39: 4 | L39: 3.75
G40: Q_09 | H40: 4.25 | I40: 3.5 | J40: 3.5 | K40: 3.75 | L40: 3.75
G41: Q_10 | H41: 4.5 | I41: 3.75 | J41: 4.5 | K41: 4.25 | L41: 4.25
G42: Q_11 | H42: 4.25 | I42: 3.75 | J42: 3.75 | K42: 4.25 | L42: 4
G43: Q_12 | H43: 4.25 | I43: 3.75 | J43: 4 | K43: 4.25 | L43: 4.0625
G44: Q_13 | H44: 4 | I44: 3.75 | J44: 3.75 | K44: 3.75 | L44: 3.8125
... G56: Q_25 | H56: 3.75 | I56: 3.5 | J56: 3.5 | K56: 3.75 | L56: 3.625
G57: Media | H57: =AVERAGE(_xlfn.ANCHORARRAY(H32)) -> 4.09 | I57: =AVERAGE(_xlfn.ANCHORARRAY(I32)) -> 3.55 | J57: =AVERAGE(_xlfn.ANCHORARRAY(J32)) -> 3.68 | K57: =AVERAGE(_xlfn.ANCHORARRAY(K32)) -> 3.88 | L57: =AVERAGE(_xlfn.ANCHORARRAY(L32)) -> 3.8

Sheet 1Year3
G1: PRG_01 | K1: PRG_02 | O1: PRG_03 | S1: PRG_04 | W1: PRG_05 | AA1: PRG_06 | AE1: PRG_07 | AI1: PRG_08 | AM1: PRG_09 | AQ1: PRG_10 | AU1: PRG_11 | AY1: PRG_12 | BC1: PRG_13 | BG1: PRG_14 | BK1: PRG_15 | BO1: PRG_16 | BS1: PRG_17 | BW1: PRG_18 | CA1: PRG_19 | CE1: PRG_20 | CI1: PRG_21 | CM1: PRG_22 | CQ1: PRG_23 | CU1: PRG_24 | CY1: PRG_25
F2: =ROUND(AVERAGE(G3:DB3),2) -> 3.57 | G2: =ROUND(AVERAGE(G3:J3),2) -> 3.09 | K2: =ROUND(AVERAGE(K3:N3),2) -> 4 | O2: =ROUND(AVERAGE(O3:R3),2) -> 3.75 | S2: =ROUND(AVERAGE(S3:V3),2) -> 3.92 | W2: =ROUND(AVERAGE(W3:Z3),2) -> 2.75 | AA2: =ROUND(AVERAGE(AA3:AD3),2) -> 3.75 | AE2: =ROUND(AVERAGE(AE3:AH3),2) -> 3.92 | AI2: =ROUND(AVERAGE(AI3:AL3),2) -> 4 | AM2: =ROUND(AVERAGE(AM3:AP3),2) -> 3.08 | AQ2: =ROUND(AVERAGE(AQ3:AT3),2) -> 4 | AU2: =ROUND(AVERAGE(AU3:AX3),2) -> 4.33 | AY2: =ROUND(AVERAGE(AY3:BB3),2) -> 3.92 | BC2: =ROUND(AVERAGE(BC3:BF3),2) -> 4 | BG2: =ROUND(AVERAGE(BG3:BJ3),2) -> 2.84 | BK2: =ROUND(AVERAGE(BK3:BN3),2) -> 4.08 | BO2: =ROUND(AVERAGE(BO3:BR3),2) -> 3.08 | BS2: =ROUND(AVERAGE(BS3:BV3),2) -> 3.67 | BW2: =ROUND(AVERAGE(BW3:BZ3),2) -> 3.92 | CA2: =ROUND(AVERAGE(CA3:CD3),2) -> 2.5 | CE2: =ROUND(AVERAGE(CE3:CH3),2) -> 2.5 | CI2: =ROUND(AVERAGE(CI3:CL3),2) -> 3.58 | CM2: =ROUND(AVERAGE(CM3:CP3),2) -> 3.17 | CQ2: =ROUND(AVERAGE(CQ3:CT3),2) -> 3.75 | CU2: =ROUND(AVERAGE(CU3:CX3),2) -> 4 | CY2: =ROUND(AVERAGE(CY3:DB3),2) -> 3.59
C3: =ROUND(AVERAGE(C5:C51),2) -> 3 | D3: =ROUND(AVERAGE(D5:D51),2) -> 4 | G3: =ROUND(AVERAGE(G5:G20),2) -> 3.67 | H3: =ROUND(AVERAGE(H5:H20),2) -> 2.67 | I3: =ROUND(AVERAGE(I5:I20),2) -> 3.33 | J3: =ROUND(AVERAGE(J5:J20),2) -> 2.67 | K3: =ROUND(AVERAGE(K5:K20),2) -> 3.67 | L3: =ROUND(AVERAGE(L5:L20),2) -> 4.33 | M3: =ROUND(AVERAGE(M5:M20),2) -> 4 | N3: =ROUND(AVERAGE(N5:N20),2) -> 4 | ... DB3: =ROUND(AVERAGE(DB5:DB20),2) -> 3.67
B4: ¿Cuantos años de experiencia tienes enseñando Python? | C4: ¿Con qué frecuencia utiliza modelos de IA para apoyarte en la práctica docente? | D4: ¿Cual es tu actitud hacia el uso de la IA en educación? | E4: ¿Consideras que la IA es capaz de sustituir la creación manual de exámenes de programación a corto plazo? | F4: Espacio libre. Deja los comentarios que creas oportunos. | G4: Pregunta 1 [Claridad técnica] | H4: Pregunta 1 [Nivel de dificultad adecuado] | I4: Pregunta 1 [Calidad de los distractores] | J4: Pregunta 1 [Validez pedagógica] | K4: Pregunta 2 [Claridad técnica] | L4: Pregunta 2 [Nivel de dificultad adecuado] | M4: Pregunta 2 [Calidad de los distractores] | N4: Pregunta 2 [Validez pedagógica] | O4: Pregunta 3 [Claridad técnica] | P4: Pregunta 3 [Nivel de dificultad adecuado] | Q4: Pregunta 3 [Calidad de los distractores] | R4: Pregunta 3 [Validez pedagógica] | S4: Pregunta 4 [Claridad técnica] | T4: Pregunta 4 [Nivel de dificultad adecuado] | U4: Pregunta 4 [Calidad de los distractores] | V4: Pregunta 4 [Validez pedagógica] | W4: Pregunta 5 [Claridad técnica] | X4: Pregunta 5 [Nivel de dificultad adecuado] | Y4: Pregunta 5 [Calidad de los distractores] | Z4: Pregunta 5 [Validez pedagógica] | AA4: Pregunta 6 [Claridad técnica] | AB4: Pregunta 6 [Nivel de dificultad adecuado] | AC4: Pregunta 6 [Calidad de los distractores] | AD4: Pregunta 6 [Validez pedagógica] | AE4: Pregunta 7 [Claridad técnica] | AF4: Pregunta 7 [Nivel de dificultad adecuado] | AG4: Pregunta 7 [Calidad de los distractores] | AH4: Pregunta 7 [Validez pedagógica] | AI4: Pregunta 8 [Claridad técnica] | AJ4: Pregunta 8 [Nivel de dificultad adecuado] | AK4: Pregunta 8 [Calidad de los distractores] | AL4: Pregunta 8 [Validez pedagógica] | AM4: Pregunta 9 [Claridad técnica] | AN4: Pregunta 9 [Nivel de dificultad adecuado] | AO4: Pregunta 9 [Calidad de los distractores] | AP4: Pregunta 9 [Validez pedagógica] | AQ4: Pregunta 10 [Claridad técnica] | AR4: Pregunta 10 [Nivel de dificultad adecuado] | AS4: Pregunta 10 [Calidad de los distractores] | AT4: Pregunta 10 [Validez pedagógica] | AU4: Pregunta 11 [Claridad técnica] | AV4: Pregunta 11 [Nivel de dificultad adecuado] | AW4: Pregunta 11 [Calidad de los distractores] | AX4: Pregunta 11 [Validez pedagógica] | AY4: Pregunta 12 [Claridad técnica] | AZ4: Pregunta 12 [Nivel de dificultad adecuado] | BA4: Pregunta 12 [Calidad de los distractores] | BB4: Pregunta 12 [Validez pedagógica] | BC4: Pregunta 13 [Claridad técnica] | BD4: Pregunta 13 [Nivel de dificultad adecuado] | BE4: Pregunta 13 [Calidad de los distractores] | BF4: Pregunta 13 [Validez pedagógica] | BG4: Pregunta 14 [Claridad técnica] | BH4: Pregunta 14 [Nivel de dificultad adecuado] | BI4: Pregunta 14 [Calidad de los distractores] | BJ4: Pregunta 14 [Validez pedagógica] | BK4: Pregunta 15 [Claridad técnica] | BL4: Pregunta 15 [Nivel de dificultad adecuado] | BM4: Pregunta 15 [Calidad de los distractores] | BN4: Pregunta 15 [Validez pedagógica] | BO4: Pregunta 16 [Claridad técnica] | BP4: Pregunta 16 [Nivel de dificultad adecuado] | BQ4: Pregunta 16 [Calidad de los distractores] | BR4: Pregunta 16 [Validez pedagógica] | BS4: Pregunta 17 [Claridad técnica] | BT4: Pregunta 17 [Nivel de dificultad adecuado] | BU4: Pregunta 17 [Calidad de los distractores] | BV4: Pregunta 17 [Validez pedagógica] | BW4: Pregunta 18 [Claridad técnica] | BX4: Pregunta 18 [Nivel de dificultad adecuado] | BY4: Pregunta 18 [Calidad de los distractores] | BZ4: Pregunta 18 [Validez pedagógica] | CA4: Pregunta 19 [Claridad técnica] | CB4: Pregunta 19 [Nivel de dificultad adecuado] | CC4: Pregunta 19 [Calidad de los distractores] | CD4: Pregunta 19 [Validez pedagógica] | CE4: Pregunta 20 [Claridad técnica] | CF4: Pregunta 20 [Nivel de dificultad adecuado] | CG4: Pregunta 20 [Calidad de los distractores] | CH4: Pregunta 20 [Validez pedagógica] | CI4: Pregunta 21 [Claridad técnica] | CJ4: Pregunta 21 [Nivel de dificultad adecuado] | CK4: Pregunta 21 [Calidad de los distractores] | CL4: Pregunta 21 [Validez pedagógica] | CM4: Pregunta 22 [Claridad técnica] | CN4: Pregunta 22 [Nivel de dificultad adecuado] | CO4: Pregunta 22 [Calidad de los distractores] | CP4: Pregunta 22 [Validez pedagógica] | CQ4: Pregunta 23 [Claridad técnica] | CR4: Pregunta 23 [Nivel de dificultad adecuado] | CS4: Pregunta 23 [Calidad de los distractores] | CT4: Pregunta 23 [Validez pedagógica] | CU4: Pregunta 24 [Claridad técnica] | CV4: Pregunta 24 [Nivel de dificultad adecuado] | CW4: Pregunta 24 [Calidad de los distractores] | CX4: Pregunta 24 [Validez pedagógica] | CY4: Pregunta 25 [Claridad técnica] | CZ4: Pregunta 25 [Nivel de dificultad adecuado] | DA4: Pregunta 25 [Calidad de los distractores] | DB4: Pregunta 25 [Validez pedagógica] | DC4: ¿Cuanto tiempo crees que te llevaría hacer un examen como este de 25 pegruntas sin ayuda de la IA?
B5: {=_xlfn._xlws.FILTER(Resp!B:DE, Resp!B:B="De 1 a 3 años", "No hay datos")} -> De 1 a 3 años | C5: 3 | D5: 4 | E5: Solo con supervisión | F5: 0 | G5: 4 | H5: 3 | I5: 4 | J5: 3 | K5: 3 | L5: 5 | M5: 5 | N5: 4 | O5: 4 | P5: 4 | Q5: 1 | R5: 3 | S5: 5 | T5: 4 | U5: 5 | V5: 5 | W5: 2 | X5: 1 | Y5: 2 | Z5: 2 | AA5: 4 | AB5: 4 | AC5: 5 | AD5: 4 | AE5: 3 | AF5: 4 | AG5: 4 | AH5: 4 | AI5: 4 | AJ5: 4 | AK5: 3 | AL5: 5 | AM5: 3 | AN5: 1 | AO5: 3 | AP5: 2 | AQ5: 4 | AR5: 3 | AS5: 4 | AT5: 5 | AU5: 5 | AV5: 5 | AW5: 5 | AX5: 5 | AY5: 5 | AZ5: 4 | BA5: 5 | BB5: 5 | BC5: 4 | BD5: 3 | BE5: 3 | BF5: 4 | BG5: 3 | BH5: 2 | BI5: 3 | BJ5: 3 | BK5: 5 | BL5: 5 | BM5: 2 | BN5: 5 | BO5: 3 | BP5: 2 | BQ5: 4 | BR5: 4 | BS5: 4 | BT5: 2 | BU5: 3 | BV5: 3 | BW5: 5 | BX5: 5 | BY5: 4 | BZ5: 5 | CA5: 2 | CB5: 2 | CC5: 3 | CD5: 3 | CE5: 3 | CF5: 2 | CG5: 2 | CH5: 3 | CI5: 3 | CJ5: 4 | CK5: 3 | CL5: 5 | CM5: 3 | CN5: 2 | CO5: 5 | CP5: 4 | CQ5: 3 | CR5: 2 | CS5: 4 | CT5: 4 | CU5: 5 | CV5: 5 | CW5: 5 | CX5: 5 | CY5: 4 | CZ5: 4 | DA5: 3 | DB5: 4 | DC5: 4-5 horas | DD5: 0 | DE5: 0
B6: De 1 a 3 años | C6: 4 | D6: 5 | E6: Solo con supervisión | F6: 0 | G6: 3 | H6: 3 | I6: 3 | J6: 3 | K6: 4 | L6: 4 | M6: 3 | N6: 4 | O6: 4 | P6: 5 | Q6: 4 | R6: 4 | S6: 3 | T6: 3 | U6: 3 | V6: 3 | W6: 3 | X6: 3 | Y6: 3 | Z6: 3 | AA6: 3 | AB6: 3 | AC6: 3 | AD6: 3 | AE6: 5 | AF6: 4 | AG6: 4 | AH6: 3 | AI6: 4 | AJ6: 4 | AK6: 4 | AL6: 4 | AM6: 3 | AN6: 3 | AO6: 3 | AP6: 3 | AQ6: 4 | AR6: 4 | AS6: 4 | AT6: 4 | AU6: 4 | AV6: 5 | AW6: 3 | AX6: 4 | AY6: 3 | AZ6: 3 | BA6: 3 | BB6: 3 | BC6: 5 | BD6: 5 | BE6: 5 | BF6: 5 | BG6: 3 | BH6: 3 | BI6: 3 | BJ6: 3 | BK6: 3 | BL6: 4 | BM6: 4 | BN6: 5 | BO6: 3 | BP6: 3 | BQ6: 3 | BR6: 3 | BS6: 4 | BT6: 4 | BU6: 4 | BV6: 4 | BW6: 4 | BX6: 4 | BY6: 4 | BZ6: 4 | CA6: 3 | CB6: 3 | CC6: 3 | CD6: 3 | CE6: 4 | CF6: 4 | CG6: 4 | CH6: 4 | CI6: 3 | CJ6: 3 | CK6: 3 | CL6: 3 | CM6: 3 | CN6: 3 | CO6: 3 | CP6: 3 | CQ6: 4 | CR6: 4 | CS6: 4 | CT6: 4 | CU6: 3 | CV6: 3 | CW6: 3 | CX6: 3 | CY6: 3 | CZ6: 3 | DA6: 3 | DB6: 3 | DC6: 2-3 horas | DD6: 0 | DE6: 0
B7: De 1 a 3 años | C7: 2 | D7: 3 | E7: Solo con supervisión | F7: El test por si solo no es relevante. La relevancia reside en que la prueba sea acorde a las competencias y contenidos abordados a lo largo del curso. Por qué tanto peso a las expresiones regulares? Por qué no hay más preguntas sobre el flujo de ejecución de un programa? Está bien balanceado el tipo de preguntas y dificultad? Y por último, es un examen de tipo test lo más adecuado para un módulo de programación? | G7: 4 | H7: 2 | I7: 3 | J7: 2 | K7: 4 | L7: 4 | M7: 4 | N7: 4 | O7: 4 | P7: 4 | Q7: 4 | R7: 4 | S7: 4 | T7: 4 | U7: 4 | V7: 4 | W7: 4 | X7: 2 | Y7: 4 | Z7: 4 | AA7: 4 | AB7: 4 | AC7: 4 | AD7: 4 | AE7: 4 | AF7: 4 | AG7: 4 | AH7: 4 | AI7: 4 | AJ7: 4 | AK7: 4 | AL7: 4 | AM7: 4 | AN7: 4 | AO7: 4 | AP7: 4 | AQ7: 4 | AR7: 4 | AS7: 4 | AT7: 4 | AU7: 4 | AV7: 4 | AW7: 4 | AX7: 4 | AY7: 4 | AZ7: 4 | BA7: 4 | BB7: 4 | BC7: 4 | BD7: 3 | BE7: 4 | BF7: 3 | BG7: 3 | BH7: 3 | BI7: 3 | BJ7: 2 | BK7: 4 | BL7: 4 | BM7: 4 | BN7: 4 | BO7: 3 | BP7: 3 | BQ7: 3 | BR7: 3 | BS7: 4 | BT7: 4 | BU7: 4 | BV7: 4 | BW7: 3 | BX7: 3 | BY7: 3 | BZ7: 3 | CA7: 2 | CB7: 2 | CC7: 2 | CD7: 2 | CE7: 1 | CF7: 1 | CG7: 1 | CH7: 1 | CI7: 4 | CJ7: 4 | CK7: 4 | CL7: 4 | CM7: 3 | CN7: 3 | CO7: 3 | CP7: 3 | CQ7: 4 | CR7: 4 | CS7: 4 | CT7: 4 | CU7: 4 | CV7: 4 | CW7: 4 | CX7: 4 | CY7: 4 | CZ7: 4 | DA7: 4 | DB7: 4 | DC7: 1 hora | DD7: 0 | DE7: 0
H22: =((COLUMN()-8)*4)+7 -> 7 | I22: =((COLUMN()-8)*4)+7 -> 11 | J22: =((COLUMN()-8)*4)+7 -> 15 | K22: =((COLUMN()-8)*4)+7 -> 19 | L22: =((COLUMN()-8)*4)+7 -> 23 | M22: =((COLUMN()-8)*4)+7 -> 27 | N22: =((COLUMN()-8)*4)+7 -> 31 | O22: =((COLUMN()-8)*4)+7 -> 35 | ... AF22: =((COLUMN()-8)*4)+7 -> 103
E23: Claridad técnica | H23: {=INDEX($A:$FF,3,H$22)} -> 3.67 | I23: {=INDEX($A:$FF,3,I$22)} -> 3.67 | J23: {=INDEX($A:$FF,3,J$22)} -> 4 | K23: {=INDEX($A:$FF,3,K$22)} -> 4 | L23: {=INDEX($A:$FF,3,L$22)} -> 3 | M23: {=INDEX($A:$FF,3,M$22)} -> 3.67 | N23: {=INDEX($A:$FF,3,N$22)} -> 4 | O23: {=INDEX($A:$FF,3,O$22)} -> 4 | ... AF23: {=INDEX($A:$FF,3,AF$22)} -> 3.67
E24: Nivel de dificultad adecuado | H24: {=INDEX($A:$FF,3,H$22+1)} -> 2.67 | I24: {=INDEX($A:$FF,3,I$22+1)} -> 4.33 | J24: {=INDEX($A:$FF,3,J$22+1)} -> 4.33 | K24: {=INDEX($A:$FF,3,K$22+1)} -> 3.67 | L24: {=INDEX($A:$FF,3,L$22+1)} -> 2 | M24: {=INDEX($A:$FF,3,M$22+1)} -> 3.67 | N24: {=INDEX($A:$FF,3,N$22+1)} -> 4 | O24: {=INDEX($A:$FF,3,O$22+1)} -> 4 | ... AF24: {=INDEX($A:$FF,3,AF$22+1)} -> 3.67
E25: Calidad de los distractores | H25: {=INDEX($A:$FF,3,H$22+2)} -> 3.33 | I25: {=INDEX($A:$FF,3,I$22+2)} -> 4 | J25: {=INDEX($A:$FF,3,J$22+2)} -> 3 | K25: {=INDEX($A:$FF,3,K$22+2)} -> 4 | L25: {=INDEX($A:$FF,3,L$22+2)} -> 3 | M25: {=INDEX($A:$FF,3,M$22+2)} -> 4 | N25: {=INDEX($A:$FF,3,N$22+2)} -> 4 | O25: {=INDEX($A:$FF,3,O$22+2)} -> 3.67 | ... AF25: {=INDEX($A:$FF,3,AF$22+2)} -> 3.33
E26: Validez pedagógica | H26: {=INDEX($A:$FF,3,H$22+3)} -> 2.67 | I26: {=INDEX($A:$FF,3,I$22+3)} -> 4 | J26: {=INDEX($A:$FF,3,J$22+3)} -> 3.67 | K26: {=INDEX($A:$FF,3,K$22+3)} -> 4 | L26: {=INDEX($A:$FF,3,L$22+3)} -> 3 | M26: {=INDEX($A:$FF,3,M$22+3)} -> 3.67 | N26: {=INDEX($A:$FF,3,N$22+3)} -> 3.67 | O26: {=INDEX($A:$FF,3,O$22+3)} -> 4.33 | ... AF26: {=INDEX($A:$FF,3,AF$22+3)} -> 3.67
E27: Promedio | H27: =AVERAGE(H23:H26) -> 3.085 | I27: =AVERAGE(I23:I26) -> 4 | J27: =AVERAGE(J23:J26) -> 3.75 | K27: =AVERAGE(K23:K26) -> 3.9175 | L27: =AVERAGE(L23:L26) -> 2.75 | M27: =AVERAGE(M23:M26) -> 3.7525 | N27: =AVERAGE(N23:N26) -> 3.9175 | O27: =AVERAGE(O23:O26) -> 4 | ... AF27: =AVERAGE(AF23:AF26) -> 3.585
H28: 1 | I28: 2 | J28: 3 | K28: 4 | L28: 5 | M28: 6 | N28: 7 | O28: 8 | P28: 9 | Q28: 10 | R28: 11 | S28: 12 | T28: 13 | U28: 14 | V28: 15 | W28: 16 | X28: 17 | Y28: 18 | Z28: 19 | AA28: 20 | AB28: 21 | AC28: 22 | AD28: 23 | AE28: 24 | AF28: 25
H31: =E23 -> Claridad técnica | I31: =E24 -> Nivel de dificultad adecuado | J31: =E25 -> Calidad de los distractores | K31: =E26 -> Validez pedagógica | L31: Media
G32: Q_01 | H32: {=TRANSPOSE(H23:AF23)} -> 3.67 | I32: {=TRANSPOSE(H24:AF24)} -> 2.67 | J32: {=TRANSPOSE(H25:AF25)} -> 3.33 | K32: {=TRANSPOSE(H26:AF26)} -> 2.67 | L32: {=TRANSPOSE(H27:AF27)} -> 3.085
G33: Q_02 | H33: 3.67 | I33: 4.33 | J33: 4 | K33: 4 | L33: 4
G34: Q_03 | H34: 4 | I34: 4.33 | J34: 3 | K34: 3.67 | L34: 3.75
G35: Q_04 | H35: 4 | I35: 3.67 | J35: 4 | K35: 4 | L35: 3.9175
G36: Q_05 | H36: 3 | I36: 2 | J36: 3 | K36: 3 | L36: 2.75
G37: Q_06 | H37: 3.67 | I37: 3.67 | J37: 4 | K37: 3.67 | L37: 3.7525
G38: Q_07 | H38: 4 | I38: 4 | J38: 4 | K38: 3.67 | L38: 3.9175
G39: Q_08 | H39: 4 | I39: 4 | J39: 3.67 | K39: 4.33 | L39: 4
G40: Q_09 | H40: 3.33 | I40: 2.67 | J40: 3.33 | K40: 3 | L40: 3.0825
G41: Q_10 | H41: 4 | I41: 3.67 | J41: 4 | K41: 4.33 | L41: 4
G42: Q_11 | H42: 4.33 | I42: 4.67 | J42: 4 | K42: 4.33 | L42: 4.3325
G43: Q_12 | H43: 4 | I43: 3.67 | J43: 4 | K43: 4 | L43: 3.9175
G44: Q_13 | H44: 4.33 | I44: 3.67 | J44: 4 | K44: 4 | L44: 4
... G56: Q_25 | H56: 3.67 | I56: 3.67 | J56: 3.33 | K56: 3.67 | L56: 3.585
G57: Media | H57: =AVERAGE(_xlfn.ANCHORARRAY(H32)) -> 3.6268 | I57: =AVERAGE(_xlfn.ANCHORARRAY(I32)) -> 3.4408 | J57: =AVERAGE(_xlfn.ANCHORARRAY(J32)) -> 3.5464 | K57: =AVERAGE(_xlfn.ANCHORARRAY(K32)) -> 3.654 | L57: =AVERAGE(_xlfn.ANCHORARRAY(L32)) -> 3.567

Sheet 3Year7
G1: PRG_01 | K1: PRG_02 | O1: PRG_03 | S1: PRG_04 | W1: PRG_05 | AA1: PRG_06 | AE1: PRG_07 | AI1: PRG_08 | AM1: PRG_09 | AQ1: PRG_10 | AU1: PRG_11 | AY1: PRG_12 | BC1: PRG_13 | BG1: PRG_14 | BK1: PRG_15 | BO1: PRG_16 | BS1: PRG_17 | BW1: PRG_18 | CA1: PRG_19 | CE1: PRG_20 | CI1: PRG_21 | CM1: PRG_22 | CQ1: PRG_23 | CU1: PRG_24 | CY1: PRG_25
F2: =ROUND(AVERAGE(G3:DB3),2) -> 4.36 | G2: =ROUND(AVERAGE(G3:J3),2) -> 3.5 | K2: =ROUND(AVERAGE(K3:N3),2) -> 4.42 | O2: =ROUND(AVERAGE(O3:R3),2) -> 4.67 | S2: =ROUND(AVERAGE(S3:V3),2) -> 4.67 | W2: =ROUND(AVERAGE(W3:Z3),2) -> 4 | AA2: =ROUND(AVERAGE(AA3:AD3),2) -> 4.33 | AE2: =ROUND(AVERAGE(AE3:AH3),2) -> 4.25 | AI2: =ROUND(AVERAGE(AI3:AL3),2) -> 4.25 | AM2: =ROUND(AVERAGE(AM3:AP3),2) -> 4.33 | AQ2: =ROUND(AVERAGE(AQ3:AT3),2) -> 4.59 | AU2: =ROUND(AVERAGE(AU3:AX3),2) -> 4.67 | AY2: =ROUND(AVERAGE(AY3:BB3),2) -> 4.67 | BC2: =ROUND(AVERAGE(BC3:BF3),2) -> 4.17 | BG2: =ROUND(AVERAGE(BG3:BJ3),2) -> 4.67 | BK2: =ROUND(AVERAGE(BK3:BN3),2) -> 4.42 | BO2: =ROUND(AVERAGE(BO3:BR3),2) -> 4.17 | BS2: =ROUND(AVERAGE(BS3:BV3),2) -> 4.59 | BW2: =ROUND(AVERAGE(BW3:BZ3),2) -> 4.17 | CA2: =ROUND(AVERAGE(CA3:CD3),2) -> 4.5 | CE2: =ROUND(AVERAGE(CE3:CH3),2) -> 4.5 | CI2: =ROUND(AVERAGE(CI3:CL3),2) -> 3.67 | CM2: =ROUND(AVERAGE(CM3:CP3),2) -> 4 | CQ2: =ROUND(AVERAGE(CQ3:CT3),2) -> 4.59 | CU2: =ROUND(AVERAGE(CU3:CX3),2) -> 4.59 | CY2: =ROUND(AVERAGE(CY3:DB3),2) -> 4.67
C3: =ROUND(AVERAGE(C5:C51),2) -> 4.67 | D3: =ROUND(AVERAGE(D5:D51),2) -> 4.33 | G3: =ROUND(AVERAGE(G5:G20),2) -> 3.67 | H3: =ROUND(AVERAGE(H5:H20),2) -> 2.67 | I3: =ROUND(AVERAGE(I5:I20),2) -> 4 | J3: =ROUND(AVERAGE(J5:J20),2) -> 3.67 | K3: =ROUND(AVERAGE(K5:K20),2) -> 4.67 | L3: =ROUND(AVERAGE(L5:L20),2) -> 4.67 | M3: =ROUND(AVERAGE(M5:M20),2) -> 4 | N3: =ROUND(AVERAGE(N5:N20),2) -> 4.33 | ... DB3: =ROUND(AVERAGE(DB5:DB20),2) -> 4.67
